exception 'Exception' with message 'The my exception' in D:\Web\nette\_trunk\tests\Debug\test.exception.php:26
Stack trace:
#0 D:\Web\nette\_trunk\tests\Debug\test.exception.php(20): third(Array)
#1 D:\Web\nette\_trunk\tests\Debug\test.exception.php(13): second(true, false)
#2 D:\Web\nette\_trunk\tests\Debug\test.exception.php(30): first(10, 'any string')
#3 {main}
PHP version 5.2.6
Nette Framework version 0.7.5
