
Sending mail with message 'exception 'FatalErrorException' with message 'Error generated by trigger_error' in D:\Web\nette\_trunk\tests\Debug\test.logging.php:45
Stack trace:
#0 [internal function]: Debug::errorHandler(256, 'Error generated...', 'D:\Web\nette\_t...', 45, Array)
#1 D:\Web\nette\_trunk\tests\Debug\test.logging.php(45): trigger_error('Error generated...', 256)
#2 D:\Web\nette\_trunk\tests\Debug\test.logging.php(38): third(Array)
#3 D:\Web\nette\_trunk\tests\Debug\test.logging.php(31): second(true, false)
#4 D:\Web\nette\_trunk\tests\Debug\test.logging.php(49): first(10, 'any string')
#5 {main}'
