exception 'FatalErrorException' with message 'Error generated by trigger_error' in D:\Web\nette\_trunk\tests\Debug\test.error.php:29
Stack trace:
#0 [internal function]: Debug::errorHandler(256, 'Error generated...', 'D:\Web\nette\_t...', 29, Array)
#1 D:\Web\nette\_trunk\tests\Debug\test.error.php(29): trigger_error('Error generated...', 256)
#2 D:\Web\nette\_trunk\tests\Debug\test.error.php(23): third(Array)
#3 D:\Web\nette\_trunk\tests\Debug\test.error.php(16): second(true, false)
#4 D:\Web\nette\_trunk\tests\Debug\test.error.php(33): first(10, 'any string')
#5 {main}
Report generated at 2008/01/23 00:00:00
PHP 5.2.9
Nette Framework 0.8 (revision $WCREV$ released on $WCDATE$)
